{
 "cells": [
  {
   "cell_type": "code",
   "execution_count": 3,
   "metadata": {},
   "outputs": [
    {
     "name": "stdout",
     "output_type": "stream",
     "text": [
      "[0.631 0.639 0.31  0.054 1.    0.    0.   ]\n",
      "Model: \"sequential_2\"\n",
      "_________________________________________________________________\n",
      " Layer (type)                Output Shape              Param #   \n",
      "=================================================================\n",
      " dense_6 (Dense)             (None, 64)                512       \n",
      "                                                                 \n",
      " dense_7 (Dense)             (None, 64)                4160      \n",
      "                                                                 \n",
      " dense_8 (Dense)             (None, 1)                 65        \n",
      "                                                                 \n",
      "=================================================================\n",
      "Total params: 4,737\n",
      "Trainable params: 4,737\n",
      "Non-trainable params: 0\n",
      "_________________________________________________________________\n",
      "None\n",
      "Epoch 1/1000\n",
      "WARNING:tensorflow:Model was constructed with shape (None, 7) for input KerasTensor(type_spec=TensorSpec(shape=(None, 7), dtype=tf.float32, name='dense_6_input'), name='dense_6_input', description=\"created by layer 'dense_6_input'\"), but it was called on an input with incompatible shape (None,).\n"
     ]
    },
    {
     "ename": "ValueError",
     "evalue": "in user code:\n\n    File \"C:\\Users\\danny\\anaconda3\\lib\\site-packages\\keras\\engine\\training.py\", line 1249, in train_function  *\n        return step_function(self, iterator)\n    File \"C:\\Users\\danny\\anaconda3\\lib\\site-packages\\keras\\engine\\training.py\", line 1233, in step_function  **\n        outputs = model.distribute_strategy.run(run_step, args=(data,))\n    File \"C:\\Users\\danny\\anaconda3\\lib\\site-packages\\keras\\engine\\training.py\", line 1222, in run_step  **\n        outputs = model.train_step(data)\n    File \"C:\\Users\\danny\\anaconda3\\lib\\site-packages\\keras\\engine\\training.py\", line 1023, in train_step\n        y_pred = self(x, training=True)\n    File \"C:\\Users\\danny\\anaconda3\\lib\\site-packages\\keras\\utils\\traceback_utils.py\", line 70, in error_handler\n        raise e.with_traceback(filtered_tb) from None\n    File \"C:\\Users\\danny\\anaconda3\\lib\\site-packages\\keras\\engine\\input_spec.py\", line 250, in assert_input_compatibility\n        raise ValueError(\n\n    ValueError: Exception encountered when calling layer 'sequential_2' (type Sequential).\n    \n    Input 0 of layer \"dense_6\" is incompatible with the layer: expected min_ndim=2, found ndim=1. Full shape received: (None,)\n    \n    Call arguments received by layer 'sequential_2' (type Sequential):\n      • inputs=tf.Tensor(shape=(None,), dtype=float32)\n      • training=True\n      • mask=None\n",
     "output_type": "error",
     "traceback": [
      "\u001b[1;31m---------------------------------------------------------------------------\u001b[0m",
      "\u001b[1;31mValueError\u001b[0m                                Traceback (most recent call last)",
      "\u001b[1;32mc:\\Users\\danny\\dev\\machine-learning_CT5170\\CT5170_assignment3\\app\\assignment_3_22240224.ipynb Cell 1\u001b[0m in \u001b[0;36m<cell line: 29>\u001b[1;34m()\u001b[0m\n\u001b[0;32m     <a href='vscode-notebook-cell:/c%3A/Users/danny/dev/machine-learning_CT5170/CT5170_assignment3/app/assignment_3_22240224.ipynb#W0sZmlsZQ%3D%3D?line=24'>25</a>\u001b[0m \u001b[39mprint\u001b[39m(model\u001b[39m.\u001b[39msummary())\n\u001b[0;32m     <a href='vscode-notebook-cell:/c%3A/Users/danny/dev/machine-learning_CT5170/CT5170_assignment3/app/assignment_3_22240224.ipynb#W0sZmlsZQ%3D%3D?line=26'>27</a>\u001b[0m EPOCHS \u001b[39m=\u001b[39m \u001b[39m1000\u001b[39m\n\u001b[1;32m---> <a href='vscode-notebook-cell:/c%3A/Users/danny/dev/machine-learning_CT5170/CT5170_assignment3/app/assignment_3_22240224.ipynb#W0sZmlsZQ%3D%3D?line=28'>29</a>\u001b[0m november13 \u001b[39m=\u001b[39m model\u001b[39m.\u001b[39;49mfit(X_train[\u001b[39m0\u001b[39;49m], Y_train, epochs\u001b[39m=\u001b[39;49mEPOCHS, validation_split\u001b[39m=\u001b[39;49m\u001b[39m0.2\u001b[39;49m, verbose\u001b[39m=\u001b[39;49m\u001b[39m1\u001b[39;49m)\n",
      "File \u001b[1;32m~\\anaconda3\\lib\\site-packages\\keras\\utils\\traceback_utils.py:70\u001b[0m, in \u001b[0;36mfilter_traceback.<locals>.error_handler\u001b[1;34m(*args, **kwargs)\u001b[0m\n\u001b[0;32m     67\u001b[0m     filtered_tb \u001b[39m=\u001b[39m _process_traceback_frames(e\u001b[39m.\u001b[39m__traceback__)\n\u001b[0;32m     68\u001b[0m     \u001b[39m# To get the full stack trace, call:\u001b[39;00m\n\u001b[0;32m     69\u001b[0m     \u001b[39m# `tf.debugging.disable_traceback_filtering()`\u001b[39;00m\n\u001b[1;32m---> 70\u001b[0m     \u001b[39mraise\u001b[39;00m e\u001b[39m.\u001b[39mwith_traceback(filtered_tb) \u001b[39mfrom\u001b[39;00m \u001b[39mNone\u001b[39m\n\u001b[0;32m     71\u001b[0m \u001b[39mfinally\u001b[39;00m:\n\u001b[0;32m     72\u001b[0m     \u001b[39mdel\u001b[39;00m filtered_tb\n",
      "File \u001b[1;32m~\\AppData\\Local\\Temp\\__autograph_generated_filet252qa53.py:15\u001b[0m, in \u001b[0;36mouter_factory.<locals>.inner_factory.<locals>.tf__train_function\u001b[1;34m(iterator)\u001b[0m\n\u001b[0;32m     13\u001b[0m \u001b[39mtry\u001b[39;00m:\n\u001b[0;32m     14\u001b[0m     do_return \u001b[39m=\u001b[39m \u001b[39mTrue\u001b[39;00m\n\u001b[1;32m---> 15\u001b[0m     retval_ \u001b[39m=\u001b[39m ag__\u001b[39m.\u001b[39mconverted_call(ag__\u001b[39m.\u001b[39mld(step_function), (ag__\u001b[39m.\u001b[39mld(\u001b[39mself\u001b[39m), ag__\u001b[39m.\u001b[39mld(iterator)), \u001b[39mNone\u001b[39;00m, fscope)\n\u001b[0;32m     16\u001b[0m \u001b[39mexcept\u001b[39;00m:\n\u001b[0;32m     17\u001b[0m     do_return \u001b[39m=\u001b[39m \u001b[39mFalse\u001b[39;00m\n",
      "\u001b[1;31mValueError\u001b[0m: in user code:\n\n    File \"C:\\Users\\danny\\anaconda3\\lib\\site-packages\\keras\\engine\\training.py\", line 1249, in train_function  *\n        return step_function(self, iterator)\n    File \"C:\\Users\\danny\\anaconda3\\lib\\site-packages\\keras\\engine\\training.py\", line 1233, in step_function  **\n        outputs = model.distribute_strategy.run(run_step, args=(data,))\n    File \"C:\\Users\\danny\\anaconda3\\lib\\site-packages\\keras\\engine\\training.py\", line 1222, in run_step  **\n        outputs = model.train_step(data)\n    File \"C:\\Users\\danny\\anaconda3\\lib\\site-packages\\keras\\engine\\training.py\", line 1023, in train_step\n        y_pred = self(x, training=True)\n    File \"C:\\Users\\danny\\anaconda3\\lib\\site-packages\\keras\\utils\\traceback_utils.py\", line 70, in error_handler\n        raise e.with_traceback(filtered_tb) from None\n    File \"C:\\Users\\danny\\anaconda3\\lib\\site-packages\\keras\\engine\\input_spec.py\", line 250, in assert_input_compatibility\n        raise ValueError(\n\n    ValueError: Exception encountered when calling layer 'sequential_2' (type Sequential).\n    \n    Input 0 of layer \"dense_6\" is incompatible with the layer: expected min_ndim=2, found ndim=1. Full shape received: (None,)\n    \n    Call arguments received by layer 'sequential_2' (type Sequential):\n      • inputs=tf.Tensor(shape=(None,), dtype=float32)\n      • training=True\n      • mask=None\n"
     ]
    }
   ],
   "source": [
    "from utils import *\n",
    "from model import *\n",
    "\n",
    "import numpy as np\n",
    "# import pandas as pd\n",
    "# import seaborn\n",
    "\n",
    "\n",
    "# First we need to process our data\n",
    "\n",
    "df = load_data('../data/train.csv')\n",
    "df = normalise_data(df)\n",
    "batches = get_time_series_batches(df)\n",
    "\n",
    "years = list(batches.keys())\n",
    "# print(years)\n",
    "# print(batches[years[0]].keys())\n",
    "# first_batch = batche\n",
    "batch = batches[years[0]].get('11')\n",
    "X_train, Y_train = split_attrs_labels(batch)\n",
    "\n",
    "print(X_train[0, :])\n",
    "\n",
    "model = create_model(X_train[0].shape)\n",
    "print(model.summary())\n",
    "\n",
    "EPOCHS = 1000\n",
    "\n",
    "november13 = model.fit(X_train[0], Y_train, epochs=EPOCHS, validation_split=0.2, verbose=1)"
   ]
  },
  {
   "cell_type": "code",
   "execution_count": null,
   "metadata": {},
   "outputs": [],
   "source": []
  }
 ],
 "metadata": {
  "kernelspec": {
   "display_name": "Python ('newenv')",
   "language": "python",
   "name": "python3"
  },
  "language_info": {
   "codemirror_mode": {
    "name": "ipython",
    "version": 3
   },
   "file_extension": ".py",
   "mimetype": "text/x-python",
   "name": "python",
   "nbconvert_exporter": "python",
   "pygments_lexer": "ipython3",
   "version": "3.9.12"
  },
  "orig_nbformat": 4,
  "vscode": {
   "interpreter": {
    "hash": "25a19fbe0a9132dfb9279d48d161753c6352f8f9478c2e74383d340069b907c3"
   }
  }
 },
 "nbformat": 4,
 "nbformat_minor": 2
}
